2023-03-21 09:32:24,812 (__init__.py:966 MainThread) ERROR - TeleBot: "Infinity polling: polling exited"
2023-03-21 09:32:24,812 (__init__.py:968 MainThread) ERROR - TeleBot: "Break infinity polling"
2023-03-21 14:25:49,956 (__init__.py:1083 MainThread) ERROR - TeleBot: "Threaded polling exception: A request to the Telegram API was unsuccessful. Error code: 409. Description: Conflict: terminated by other getUpdates request; make sure that only one bot instance is running"
2023-03-21 14:25:49,957 (__init__.py:1085 MainThread) ERROR - TeleBot: "Exception traceback:
Traceback (most recent call last):
  File "/home/kanis/.local/lib/python3.10/site-packages/telebot/__init__.py", line 1073, in __threaded_polling
    polling_thread.raise_exceptions()
  File "/home/kanis/.local/lib/python3.10/site-packages/telebot/util.py", line 109, in raise_exceptions
    raise self.exception_info
  File "/home/kanis/.local/lib/python3.10/site-packages/telebot/util.py", line 91, in run
    task(*args, **kwargs)
  File "/home/kanis/.local/lib/python3.10/site-packages/telebot/__init__.py", line 649, in __retrieve_updates
    updates = self.get_updates(offset=(self.last_update_id + 1),
  File "/home/kanis/.local/lib/python3.10/site-packages/telebot/__init__.py", line 623, in get_updates
    json_updates = apihelper.get_updates(self.token, offset, limit, timeout, allowed_updates, long_polling_timeout)
  File "/home/kanis/.local/lib/python3.10/site-packages/telebot/apihelper.py", line 321, in get_updates
    return _make_request(token, method_url, params=payload)
  File "/home/kanis/.local/lib/python3.10/site-packages/telebot/apihelper.py", line 162, in _make_request
    json_result = _check_result(method_name, result)
  File "/home/kanis/.local/lib/python3.10/site-packages/telebot/apihelper.py", line 189, in _check_result
    raise ApiTelegramException(method_name, result, result_json)
telebot.apihelper.ApiTelegramException: A request to the Telegram API was unsuccessful. Error code: 409. Description: Conflict: terminated by other getUpdates request; make sure that only one bot instance is running
"
2023-03-21 14:25:53,924 (__init__.py:1083 MainThread) ERROR - TeleBot: "Threaded polling exception: A request to the Telegram API was unsuccessful. Error code: 409. Description: Conflict: terminated by other getUpdates request; make sure that only one bot instance is running"
2023-03-21 14:25:53,924 (__init__.py:1085 MainThread) ERROR - TeleBot: "Exception traceback:
Traceback (most recent call last):
  File "/home/kanis/.local/lib/python3.10/site-packages/telebot/__init__.py", line 1073, in __threaded_polling
    polling_thread.raise_exceptions()
  File "/home/kanis/.local/lib/python3.10/site-packages/telebot/util.py", line 109, in raise_exceptions
    raise self.exception_info
  File "/home/kanis/.local/lib/python3.10/site-packages/telebot/util.py", line 91, in run
    task(*args, **kwargs)
  File "/home/kanis/.local/lib/python3.10/site-packages/telebot/__init__.py", line 649, in __retrieve_updates
    updates = self.get_updates(offset=(self.last_update_id + 1),
  File "/home/kanis/.local/lib/python3.10/site-packages/telebot/__init__.py", line 623, in get_updates
    json_updates = apihelper.get_updates(self.token, offset, limit, timeout, allowed_updates, long_polling_timeout)
  File "/home/kanis/.local/lib/python3.10/site-packages/telebot/apihelper.py", line 321, in get_updates
    return _make_request(token, method_url, params=payload)
  File "/home/kanis/.local/lib/python3.10/site-packages/telebot/apihelper.py", line 162, in _make_request
    json_result = _check_result(method_name, result)
  File "/home/kanis/.local/lib/python3.10/site-packages/telebot/apihelper.py", line 189, in _check_result
    raise ApiTelegramException(method_name, result, result_json)
telebot.apihelper.ApiTelegramException: A request to the Telegram API was unsuccessful. Error code: 409. Description: Conflict: terminated by other getUpdates request; make sure that only one bot instance is running
"
2023-03-21 14:25:58,217 (__init__.py:1083 MainThread) ERROR - TeleBot: "Threaded polling exception: A request to the Telegram API was unsuccessful. Error code: 409. Description: Conflict: terminated by other getUpdates request; make sure that only one bot instance is running"
2023-03-21 14:25:58,217 (__init__.py:1085 MainThread) ERROR - TeleBot: "Exception traceback:
Traceback (most recent call last):
  File "/home/kanis/.local/lib/python3.10/site-packages/telebot/__init__.py", line 1073, in __threaded_polling
    polling_thread.raise_exceptions()
  File "/home/kanis/.local/lib/python3.10/site-packages/telebot/util.py", line 109, in raise_exceptions
    raise self.exception_info
  File "/home/kanis/.local/lib/python3.10/site-packages/telebot/util.py", line 91, in run
    task(*args, **kwargs)
  File "/home/kanis/.local/lib/python3.10/site-packages/telebot/__init__.py", line 649, in __retrieve_updates
    updates = self.get_updates(offset=(self.last_update_id + 1),
  File "/home/kanis/.local/lib/python3.10/site-packages/telebot/__init__.py", line 623, in get_updates
    json_updates = apihelper.get_updates(self.token, offset, limit, timeout, allowed_updates, long_polling_timeout)
  File "/home/kanis/.local/lib/python3.10/site-packages/telebot/apihelper.py", line 321, in get_updates
    return _make_request(token, method_url, params=payload)
  File "/home/kanis/.local/lib/python3.10/site-packages/telebot/apihelper.py", line 162, in _make_request
    json_result = _check_result(method_name, result)
  File "/home/kanis/.local/lib/python3.10/site-packages/telebot/apihelper.py", line 189, in _check_result
    raise ApiTelegramException(method_name, result, result_json)
telebot.apihelper.ApiTelegramException: A request to the Telegram API was unsuccessful. Error code: 409. Description: Conflict: terminated by other getUpdates request; make sure that only one bot instance is running
"
2023-03-21 14:26:03,162 (__init__.py:1083 MainThread) ERROR - TeleBot: "Threaded polling exception: A request to the Telegram API was unsuccessful. Error code: 409. Description: Conflict: terminated by other getUpdates request; make sure that only one bot instance is running"
2023-03-21 14:26:03,162 (__init__.py:1085 MainThread) ERROR - TeleBot: "Exception traceback:
Traceback (most recent call last):
  File "/home/kanis/.local/lib/python3.10/site-packages/telebot/__init__.py", line 1073, in __threaded_polling
    polling_thread.raise_exceptions()
  File "/home/kanis/.local/lib/python3.10/site-packages/telebot/util.py", line 109, in raise_exceptions
    raise self.exception_info
  File "/home/kanis/.local/lib/python3.10/site-packages/telebot/util.py", line 91, in run
    task(*args, **kwargs)
  File "/home/kanis/.local/lib/python3.10/site-packages/telebot/__init__.py", line 649, in __retrieve_updates
    updates = self.get_updates(offset=(self.last_update_id + 1),
  File "/home/kanis/.local/lib/python3.10/site-packages/telebot/__init__.py", line 623, in get_updates
    json_updates = apihelper.get_updates(self.token, offset, limit, timeout, allowed_updates, long_polling_timeout)
  File "/home/kanis/.local/lib/python3.10/site-packages/telebot/apihelper.py", line 321, in get_updates
    return _make_request(token, method_url, params=payload)
  File "/home/kanis/.local/lib/python3.10/site-packages/telebot/apihelper.py", line 162, in _make_request
    json_result = _check_result(method_name, result)
  File "/home/kanis/.local/lib/python3.10/site-packages/telebot/apihelper.py", line 189, in _check_result
    raise ApiTelegramException(method_name, result, result_json)
telebot.apihelper.ApiTelegramException: A request to the Telegram API was unsuccessful. Error code: 409. Description: Conflict: terminated by other getUpdates request; make sure that only one bot instance is running
"
2023-03-21 14:26:09,613 (__init__.py:1083 MainThread) ERROR - TeleBot: "Threaded polling exception: A request to the Telegram API was unsuccessful. Error code: 409. Description: Conflict: terminated by other getUpdates request; make sure that only one bot instance is running"
2023-03-21 14:26:09,614 (__init__.py:1085 MainThread) ERROR - TeleBot: "Exception traceback:
Traceback (most recent call last):
  File "/home/kanis/.local/lib/python3.10/site-packages/telebot/__init__.py", line 1073, in __threaded_polling
    polling_thread.raise_exceptions()
  File "/home/kanis/.local/lib/python3.10/site-packages/telebot/util.py", line 109, in raise_exceptions
    raise self.exception_info
  File "/home/kanis/.local/lib/python3.10/site-packages/telebot/util.py", line 91, in run
    task(*args, **kwargs)
  File "/home/kanis/.local/lib/python3.10/site-packages/telebot/__init__.py", line 649, in __retrieve_updates
    updates = self.get_updates(offset=(self.last_update_id + 1),
  File "/home/kanis/.local/lib/python3.10/site-packages/telebot/__init__.py", line 623, in get_updates
    json_updates = apihelper.get_updates(self.token, offset, limit, timeout, allowed_updates, long_polling_timeout)
  File "/home/kanis/.local/lib/python3.10/site-packages/telebot/apihelper.py", line 321, in get_updates
    return _make_request(token, method_url, params=payload)
  File "/home/kanis/.local/lib/python3.10/site-packages/telebot/apihelper.py", line 162, in _make_request
    json_result = _check_result(method_name, result)
  File "/home/kanis/.local/lib/python3.10/site-packages/telebot/apihelper.py", line 189, in _check_result
    raise ApiTelegramException(method_name, result, result_json)
telebot.apihelper.ApiTelegramException: A request to the Telegram API was unsuccessful. Error code: 409. Description: Conflict: terminated by other getUpdates request; make sure that only one bot instance is running
"
2023-03-21 14:26:19,137 (__init__.py:1083 MainThread) ERROR - TeleBot: "Threaded polling exception: A request to the Telegram API was unsuccessful. Error code: 409. Description: Conflict: terminated by other getUpdates request; make sure that only one bot instance is running"
2023-03-21 14:26:19,137 (__init__.py:1085 MainThread) ERROR - TeleBot: "Exception traceback:
Traceback (most recent call last):
  File "/home/kanis/.local/lib/python3.10/site-packages/telebot/__init__.py", line 1073, in __threaded_polling
    polling_thread.raise_exceptions()
  File "/home/kanis/.local/lib/python3.10/site-packages/telebot/util.py", line 109, in raise_exceptions
    raise self.exception_info
  File "/home/kanis/.local/lib/python3.10/site-packages/telebot/util.py", line 91, in run
    task(*args, **kwargs)
  File "/home/kanis/.local/lib/python3.10/site-packages/telebot/__init__.py", line 649, in __retrieve_updates
    updates = self.get_updates(offset=(self.last_update_id + 1),
  File "/home/kanis/.local/lib/python3.10/site-packages/telebot/__init__.py", line 623, in get_updates
    json_updates = apihelper.get_updates(self.token, offset, limit, timeout, allowed_updates, long_polling_timeout)
  File "/home/kanis/.local/lib/python3.10/site-packages/telebot/apihelper.py", line 321, in get_updates
    return _make_request(token, method_url, params=payload)
  File "/home/kanis/.local/lib/python3.10/site-packages/telebot/apihelper.py", line 162, in _make_request
    json_result = _check_result(method_name, result)
  File "/home/kanis/.local/lib/python3.10/site-packages/telebot/apihelper.py", line 189, in _check_result
    raise ApiTelegramException(method_name, result, result_json)
telebot.apihelper.ApiTelegramException: A request to the Telegram API was unsuccessful. Error code: 409. Description: Conflict: terminated by other getUpdates request; make sure that only one bot instance is running
"
